{
 "cells": [
  {
   "cell_type": "code",
   "execution_count": 4,
   "id": "babc53c4",
   "metadata": {},
   "outputs": [
    {
     "name": "stdout",
     "output_type": "stream",
     "text": [
      "Enter a number: 0\n",
      "Cannot divide by zero.\n"
     ]
    }
   ],
   "source": [
    "#what is an exception in python ? write the difference between exception and \n",
    "#syntax\n",
    "'''\n",
    "In Python, an exception is an event that occurs during the execution of a \n",
    "program that disrupts the normal flow of the program. When an exception occurs, \n",
    "it creates an object that represents the error or exceptional condition. This \n",
    "object contains information about the type of exception and any additional \n",
    "details related to the error.\n",
    "\n",
    "Exceptions can occur due to various reasons, such as invalid input, division \n",
    "by zero, file not found, or network errors. They can be raised explicitly using \n",
    "the raise statement or automatically by the Python interpreter when it encounters\n",
    "an error condition.\n",
    "\n",
    "Exception: \n",
    "An exception occurs during the runtime of a program when a specific \n",
    "error condition or exceptional situation is encountered. It may be caused by \n",
    "factors such as invalid input, division by zero, or accessing an unavailable \n",
    "resource. Exceptions can be handled and recovered from using exception handling \n",
    "mechanisms like try and except.\n",
    "\n",
    "Syntax Error: \n",
    "A syntax error, also known as a parsing error, occurs when the Python \n",
    "interpreter encounters a statement or expression that violates the rules of the \n",
    "Python language grammar. Syntax errors are typically caused by mistakes in the \n",
    "code's structure, such as incorrect indentation, missing or misplaced punctuation,\n",
    "or improper use of keywords or operators. These errors prevent the program from \n",
    "being executed at all and need to be fixed before the code can be run successfully.\n",
    "\n",
    "exceptions occur during the runtime of a program due to specific error \n",
    "conditions, while syntax errors are detected by the Python interpreter during the\n",
    "parsing phase and prevent the program from running. Exceptions can be handled and\n",
    "recovered from using exception handling techniques, whereas syntax errors \n",
    "require code correction to resolve them.\n",
    "'''\n",
    "\n",
    "try:\n",
    "    num = int(input(\"Enter a number: \"))\n",
    "    result = 10 / num\n",
    "    print(\"Result:\", result)\n",
    "except ValueError:\n",
    "    print(\"Invalid input. Please enter a valid number.\")\n",
    "except ZeroDivisionError:\n",
    "    print(\"Cannot divide by zero.\")"
   ]
  },
  {
   "cell_type": "code",
   "execution_count": 3,
   "id": "2b5268d6",
   "metadata": {},
   "outputs": [],
   "source": [
    "#Q2. What happens when an exception is not handled? Explin with an example.\n",
    "'''\n",
    "When an exception is not handled in Python, it results in the program \n",
    "terminating abruptly, and an error message known as a traceback is displayed. \n",
    "The traceback provides information about the exception type, the line of code \n",
    "where the exception occurred, and the call stack that led to the exception.\n",
    "'''\n"
   ]
  },
  {
   "cell_type": "code",
   "execution_count": 5,
   "id": "16576c42",
   "metadata": {},
   "outputs": [
    {
     "ename": "ZeroDivisionError",
     "evalue": "division by zero",
     "output_type": "error",
     "traceback": [
      "\u001b[1;31m---------------------------------------------------------------------------\u001b[0m",
      "\u001b[1;31mZeroDivisionError\u001b[0m                         Traceback (most recent call last)",
      "\u001b[1;32m~\\AppData\\Local\\Temp\\ipykernel_8608\\2459605248.py\u001b[0m in \u001b[0;36m<module>\u001b[1;34m\u001b[0m\n\u001b[0;32m      6\u001b[0m \u001b[0mnum2\u001b[0m \u001b[1;33m=\u001b[0m \u001b[1;36m0\u001b[0m\u001b[1;33m\u001b[0m\u001b[1;33m\u001b[0m\u001b[0m\n\u001b[0;32m      7\u001b[0m \u001b[1;33m\u001b[0m\u001b[0m\n\u001b[1;32m----> 8\u001b[1;33m \u001b[0mresult\u001b[0m \u001b[1;33m=\u001b[0m \u001b[0mdivide_numbers\u001b[0m\u001b[1;33m(\u001b[0m\u001b[0mnum1\u001b[0m\u001b[1;33m,\u001b[0m \u001b[0mnum2\u001b[0m\u001b[1;33m)\u001b[0m\u001b[1;33m\u001b[0m\u001b[1;33m\u001b[0m\u001b[0m\n\u001b[0m\u001b[0;32m      9\u001b[0m \u001b[0mprint\u001b[0m\u001b[1;33m(\u001b[0m\u001b[1;34m\"Result:\"\u001b[0m\u001b[1;33m,\u001b[0m \u001b[0mresult\u001b[0m\u001b[1;33m)\u001b[0m\u001b[1;33m\u001b[0m\u001b[1;33m\u001b[0m\u001b[0m\n",
      "\u001b[1;32m~\\AppData\\Local\\Temp\\ipykernel_8608\\2459605248.py\u001b[0m in \u001b[0;36mdivide_numbers\u001b[1;34m(a, b)\u001b[0m\n\u001b[0;32m      1\u001b[0m \u001b[1;32mdef\u001b[0m \u001b[0mdivide_numbers\u001b[0m\u001b[1;33m(\u001b[0m\u001b[0ma\u001b[0m\u001b[1;33m,\u001b[0m \u001b[0mb\u001b[0m\u001b[1;33m)\u001b[0m\u001b[1;33m:\u001b[0m\u001b[1;33m\u001b[0m\u001b[1;33m\u001b[0m\u001b[0m\n\u001b[1;32m----> 2\u001b[1;33m     \u001b[0mresult\u001b[0m \u001b[1;33m=\u001b[0m \u001b[0ma\u001b[0m \u001b[1;33m/\u001b[0m \u001b[0mb\u001b[0m\u001b[1;33m\u001b[0m\u001b[1;33m\u001b[0m\u001b[0m\n\u001b[0m\u001b[0;32m      3\u001b[0m     \u001b[1;32mreturn\u001b[0m \u001b[0mresult\u001b[0m\u001b[1;33m\u001b[0m\u001b[1;33m\u001b[0m\u001b[0m\n\u001b[0;32m      4\u001b[0m \u001b[1;33m\u001b[0m\u001b[0m\n\u001b[0;32m      5\u001b[0m \u001b[0mnum1\u001b[0m \u001b[1;33m=\u001b[0m \u001b[1;36m10\u001b[0m\u001b[1;33m\u001b[0m\u001b[1;33m\u001b[0m\u001b[0m\n",
      "\u001b[1;31mZeroDivisionError\u001b[0m: division by zero"
     ]
    }
   ],
   "source": [
    "def divide_numbers(a, b):\n",
    "    result = a / b\n",
    "    return result\n",
    "\n",
    "num1 = 10\n",
    "num2 = 0\n",
    "\n",
    "result = divide_numbers(num1, num2)\n",
    "print(\"Result:\", result)"
   ]
  },
  {
   "cell_type": "code",
   "execution_count": 7,
   "id": "9c5e8d72",
   "metadata": {},
   "outputs": [],
   "source": [
    "#In this example, a function called divide_numbers() is defined to perform \n",
    "#division. It takes two numbers as input, divides the first number by the \n",
    "#second number, and returns the result. However, the second number (num2) is \n",
    "#setto zero, which will result in a ZeroDivisionError when attempting to divide \n",
    "#by zero.\n",
    "\n",
    "#When the program is executed, the division operation inside the function \n",
    "#raises a ZeroDivisionError exception. Since there is no exception handling \n",
    "#code to catch and handle this exception, the program terminates abruptly, and \n",
    "#a traceback is displayed:\n",
    "\n",
    "#The traceback provides information about the exception (ZeroDivisionError), the\n",
    "#line of code where the exception occurred (line 2 inside the divide_numbers() \n",
    "#function), and the call stack that led to the exception (line 8 in the main \n",
    "#program).\n",
    "\n",
    "#When an exception is not handled, it can lead to unexpected program termination\n",
    "#, leaving the program in an inconsistent state. Handling exceptions allows you \n",
    "#to gracefully handle errors and perform appropriate actions, such as displaying\n",
    "#error messages, logging, or taking alternative code paths to avoid program \n",
    "#crashes.\n",
    "    "
   ]
  },
  {
   "cell_type": "code",
   "execution_count": 9,
   "id": "a5d08123",
   "metadata": {},
   "outputs": [
    {
     "name": "stdout",
     "output_type": "stream",
     "text": [
      "Enter the first number: \n",
      "Invalid input. Please enter a valid integer.\n"
     ]
    }
   ],
   "source": [
    "# Q3 which python statements are used to catch and handle exceptions? with example\n",
    "#In Python, the try and except statements are used to catch and handle exceptions\n",
    "#. The try block contains the code that may potentially raise an exception, and \n",
    "#the except block is used to define the actions to be taken when a specific \n",
    "#exception occurs.\n",
    "\n",
    "try:\n",
    "    num1 = int(input(\"Enter the first number: \"))\n",
    "    num2 = int(input(\"Enter the second number: \"))\n",
    "    result = num1 / num2\n",
    "    print(\"Result:\", result)\n",
    "except ValueError:\n",
    "    print(\"Invalid input. Please enter a valid integer.\")\n",
    "except ZeroDivisionError:\n",
    "    print(\"Cannot divide by zero.\")\n",
    "    \n",
    "#Using try and except allows you to catch specific exceptions and handle them \n",
    "#gracefully. If an exception occurs within the try block, the program flow will \n",
    "#immediately jump to the corresponding except block, and the remaining code in \n",
    "#the try block will be skipped. This way, you can control how your program \n",
    "#handles exceptions and take appropriate actions based on the type of exception \n",
    "#encountered.\n",
    "\n",
    "\n",
    "\n",
    "\n",
    "\n"
   ]
  },
  {
   "cell_type": "code",
   "execution_count": 10,
   "id": "17eca0a5",
   "metadata": {},
   "outputs": [
    {
     "name": "stdout",
     "output_type": "stream",
     "text": [
      "Enter a number: 100\n",
      "Enter another number: 155\n",
      "Result: 0.6451612903225806\n",
      "Enter your age: 23\n",
      "Access granted.\n",
      "File not found.\n"
     ]
    },
    {
     "ename": "NameError",
     "evalue": "name 'file' is not defined",
     "output_type": "error",
     "traceback": [
      "\u001b[1;31m---------------------------------------------------------------------------\u001b[0m",
      "\u001b[1;31mNameError\u001b[0m                                 Traceback (most recent call last)",
      "\u001b[1;32m~\\AppData\\Local\\Temp\\ipykernel_8608\\3425944876.py\u001b[0m in \u001b[0;36m<module>\u001b[1;34m\u001b[0m\n\u001b[0;32m     69\u001b[0m     \u001b[0mprint\u001b[0m\u001b[1;33m(\u001b[0m\u001b[1;34m\"File not found.\"\u001b[0m\u001b[1;33m)\u001b[0m\u001b[1;33m\u001b[0m\u001b[1;33m\u001b[0m\u001b[0m\n\u001b[0;32m     70\u001b[0m \u001b[1;32mfinally\u001b[0m\u001b[1;33m:\u001b[0m\u001b[1;33m\u001b[0m\u001b[1;33m\u001b[0m\u001b[0m\n\u001b[1;32m---> 71\u001b[1;33m     \u001b[0mfile\u001b[0m\u001b[1;33m.\u001b[0m\u001b[0mclose\u001b[0m\u001b[1;33m(\u001b[0m\u001b[1;33m)\u001b[0m\u001b[1;33m\u001b[0m\u001b[1;33m\u001b[0m\u001b[0m\n\u001b[0m\u001b[0;32m     72\u001b[0m '''\n\u001b[0;32m     73\u001b[0m \u001b[0mIn\u001b[0m \u001b[0mthis\u001b[0m \u001b[0mexample\u001b[0m\u001b[1;33m,\u001b[0m \u001b[0mthe\u001b[0m \u001b[1;32mtry\u001b[0m \u001b[0mblock\u001b[0m \u001b[0mattempts\u001b[0m \u001b[0mto\u001b[0m \u001b[0mopen\u001b[0m \u001b[0ma\u001b[0m \u001b[0mfile\u001b[0m \u001b[0mnamed\u001b[0m \u001b[1;34m\"data.txt\"\u001b[0m \u001b[1;32mfor\u001b[0m\u001b[1;33m\u001b[0m\u001b[1;33m\u001b[0m\u001b[0m\n",
      "\u001b[1;31mNameError\u001b[0m: name 'file' is not defined"
     ]
    }
   ],
   "source": [
    "#explain with example \n",
    "#1) try except \n",
    "#2) raise \n",
    "#3) finally\n",
    "\n",
    "'''\n",
    "try-except:\n",
    "The try-except block is used to catch and handle exceptions. It allows you to \n",
    "specify the code that may raise an exception within the try block and define how\n",
    "to handle that exception within the corresponding except block.\n",
    "python\n",
    "'''\n",
    "try:\n",
    "    num1 = int(input(\"Enter a number: \"))\n",
    "    num2 = int(input(\"Enter another number: \"))\n",
    "    result = num1 / num2\n",
    "    print(\"Result:\", result)\n",
    "except ValueError:\n",
    "    print(\"Invalid input. Please enter a valid integer.\")\n",
    "except ZeroDivisionError:\n",
    "    print(\"Cannot divide by zero.\")\n",
    "'''\n",
    "In this example, the try block attempts to perform division between two numbers \n",
    "provided by the user. If a ValueError exception occurs (e.g., if the user enters\n",
    "a non-numeric value), the program will jump to the corresponding except \n",
    "ValueError block and display an error message. If a ZeroDivisionError occurs \n",
    "(e.g., if the user enters zero as the second number), the program will jump to \n",
    "the corresponding except ZeroDivisionError block and display another error \n",
    "message. The use of try-except allows you to handle different types of \n",
    "exceptions separately and provide appropriate feedback or alternative actions.\n",
    "\n",
    "'''\n",
    "'''\n",
    "raise:\n",
    "The raise statement is used to explicitly raise an exception in Python. It \n",
    "allows you to create and raise your own custom exceptions or propagate built-in \n",
    "exceptions.\n",
    "'''\n",
    "def validate_age(age):\n",
    "    if age < 0:\n",
    "        raise ValueError(\"Age cannot be negative.\")\n",
    "    elif age < 18:\n",
    "        raise ValueError(\"You must be 18 years or older.\")\n",
    "\n",
    "try:\n",
    "    user_age = int(input(\"Enter your age: \"))\n",
    "    validate_age(user_age)\n",
    "    print(\"Access granted.\")\n",
    "except ValueError as ve:\n",
    "    print(\"Error:\", str(ve))\n",
    "'''  \n",
    "In this example, a validate_age() function is defined to check if a given age \n",
    "is valid. If the age is less than zero, a custom ValueError exception is raised\n",
    "with a specific error message. If the age is less than 18, another custom \n",
    "ValueError exception is raised. In the try block, the user is prompted to enter \n",
    "their age, and the validate_age() function is called. If an exception is raised \n",
    "within the function, it will be caught in the except ValueError block, and the \n",
    "error message will be displayed.\n",
    "'''\n",
    "'''\n",
    "finally:\n",
    "The finally block is used to specify code that will be executed regardless of whether an exception was raised or not. It is generally used to perform cleanup operations, such as closing files or releasing resources, that need to be done regardless of the exception handling.\n",
    "python\n",
    "'''\n",
    "try:\n",
    "    file = open(\"data.txt\", \"r\")\n",
    "    # Perform some file operations\n",
    "except FileNotFoundError:\n",
    "    print(\"File not found.\")\n",
    "finally:\n",
    "    file.close()\n",
    "'''\n",
    "In this example, the try block attempts to open a file named \"data.txt\" for \n",
    "reading and perform some operations on it. If a FileNotFoundError exception \n",
    "occurs (e.g., the file does not exist), the program will jump to the \n",
    "corresponding except FileNotFoundError block and display an error message. \n",
    "Regardless of whether an exception occurs or not, the finally block will be \n",
    "executed, ensuring that the file is closed properly using the file.close() \n",
    "statement.\n",
    "\n",
    "The finally block is useful when you need to ensure that certain actions are \n",
    "always performed, such as closing files, releasing resources, or cleaning up \n",
    "after executing critical code, irrespective of exceptions occurring.'''"
   ]
  },
  {
   "cell_type": "code",
   "execution_count": null,
   "id": "d7d5b501",
   "metadata": {},
   "outputs": [],
   "source": [
    "#5) what are custom exceptions in python? why do we need custom exceptions?\n",
    "#explain with example."
   ]
  },
  {
   "cell_type": "code",
   "execution_count": null,
   "id": "c6f5dacd",
   "metadata": {},
   "outputs": [],
   "source": [
    "'''\n",
    "Custom exceptions in Python are user-defined exceptions that allow you to create your own exception classes to handle specific error conditions in your code. These exceptions extend the base Exception class or any of its subclasses and provide additional functionality or context-specific behavior.\n",
    "\n",
    "Here are some reasons why we need custom exceptions:\n",
    "\n",
    "Specificity: Custom exceptions allow you to define more specific error conditions that are relevant to your code or domain. By creating custom exceptions, you can provide more descriptive error messages and handle specific exceptional cases in a more meaningful way.\n",
    "\n",
    "Modularity and Reusability: Custom exceptions make your code more modular and reusable. By defining specific exceptions for different scenarios, you can easily handle those exceptions in a consistent manner across multiple parts of your codebase. It promotes code organization and helps in code maintenance and debugging.\n",
    "\n",
    "Clarity and Readability: Custom exceptions improve code clarity and readability by making it easier to understand the intention and purpose of exception handling. When you encounter a custom exception, it gives you a clear indication of the specific error condition or exceptional situation that occurred.\n",
    "'''\n",
    "class InvalidUsernameException(Exception):\n",
    "    pass\n",
    "\n",
    "def validate_username(username):\n",
    "    if len(username) < 5:\n",
    "        raise InvalidUsernameException(\"Username must be at least 5 characters long.\")\n",
    "\n",
    "try:\n",
    "    user_input = input(\"Enter a username: \")\n",
    "    validate_username(user_input)\n",
    "    print(\"Username is valid.\")\n",
    "except InvalidUsernameException as e:\n",
    "    print(\"Invalid username:\", str(e))\n",
    "\n",
    "\n",
    "    \n",
    "'''\n",
    "In this example, a custom exception called InvalidUsernameException is defined by creating a new class that extends the base Exception class. The validate_username() function checks if a given username is valid and raises the InvalidUsernameException if it is less than 5 characters long.\n",
    "\n",
    "In the try block, the user is prompted to enter a username, and the validate_username() function is called. If the username is invalid, an InvalidUsernameException is raised. This exception is caught in the except InvalidUsernameException block, and an appropriate error message is displayed.\n",
    "\n",
    "By using a custom exception, we can specifically handle the case of an invalid username in a more organized and readable manner. It also allows us to differentiate it from other exceptions and provide more specific feedback to the user.\n",
    "\n",
    "\n",
    "\n",
    "\n",
    "\n",
    "'''"
   ]
  },
  {
   "cell_type": "code",
   "execution_count": null,
   "id": "5cc82013",
   "metadata": {},
   "outputs": [],
   "source": [
    "#6) create a custom exception class. use this class to handle an exception\n",
    "\n",
    "class CustomException(Exception):\n",
    "    def __init__(self, message):\n",
    "        self.message = message\n",
    "\n",
    "def perform_operation(value):\n",
    "    if value < 0:\n",
    "        raise CustomException(\"Invalid value: Cannot perform the operation on a negative number.\")\n",
    "    # Perform some operation with the value\n",
    "\n",
    "try:\n",
    "    num = int(input(\"Enter a number: \"))\n",
    "    perform_operation(num)\n",
    "    print(\"Operation completed.\")\n",
    "except CustomException as ce:\n",
    "    print(\"Error:\", ce.message)\n"
   ]
  },
  {
   "cell_type": "code",
   "execution_count": null,
   "id": "de24c9ac",
   "metadata": {},
   "outputs": [],
   "source": []
  }
 ],
 "metadata": {
  "kernelspec": {
   "display_name": "Python 3 (ipykernel)",
   "language": "python",
   "name": "python3"
  },
  "language_info": {
   "codemirror_mode": {
    "name": "ipython",
    "version": 3
   },
   "file_extension": ".py",
   "mimetype": "text/x-python",
   "name": "python",
   "nbconvert_exporter": "python",
   "pygments_lexer": "ipython3",
   "version": "3.9.13"
  }
 },
 "nbformat": 4,
 "nbformat_minor": 5
}
